<div class="col-xs-12 col-sm-9 col-md-8 main-content">
 <section class="multi-line-signature">
  <span class="returntype">
  </span>
  <span class="name ">
   catchError
  </span>
  (
  <wbr>
  <span class="parameter" id="catchError-param-onError">
   <span class="type-annotation">
    <a class="" href="dart-core/Function-class.html">
     Function
    </a>
   </span>
   <span class="parameter-name">
    onError
   </span>
  </span>
  , {
  <span class="parameter" id="catchError-param-test">
   <span class="type-annotation">
    bool
   </span>
   <span class="parameter-name">
    test
   </span>
   (
   <span class="parameter" id="test-param-error">
    <span class="type-annotation">
     <a class="" href="dart-core/Object-class.html">
      Object
     </a>
    </span>
    <span class="parameter-name">
     error
    </span>
   </span>
   )
  </span>
  })
 </section>
 <section class="desc markdown">
  <p>
   Handles errors emitted by this
   <a class="" href="dart-async/Future-class.html">
    Future
   </a>
   .
  </p>
  <p>
   This is the asynchronous equivalent of a &#34;catch&#34; block.
  </p>
  <p>
   Returns a new
   <a class="" href="dart-async/Future-class.html">
    Future
   </a>
   that will be completed with either the result of
this future or the result of calling the
   <code>
    onError
   </code>
   callback.
  </p>
  <p>
   If this future completes with a value,
the returned future completes with the same value.
  </p>
  <p>
   If this future completes with an error,
then
   <code>
    test
   </code>
   is first called with the error value.
  </p>
  <p>
   If
   <code>
    test
   </code>
   returns false, the exception is not handled by this
   <code>
    catchError
   </code>
   ,
and the returned future completes with the same error and stack trace
as this future.
  </p>
  <p>
   If
   <code>
    test
   </code>
   returns
   <code>
    true
   </code>
   ,
   <code>
    onError
   </code>
   is called with the error and possibly stack trace,
and the returned future is completed with the result of this call
in exactly the same way as for
   <a class="" href="dart-async/Future/then.html">
    then
   </a>
   &#39;s
   <code>
    onError
   </code>
   .
  </p>
  <p>
   If
   <code>
    test
   </code>
   is omitted, it defaults to a function that always returns true.
The
   <code>
    test
   </code>
   function should not throw, but if it does, it is handled as
if the the
   <code>
    onError
   </code>
   function had thrown.
  </p>
  <p>
   Example:
  </p>
  <pre class="prettyprint lang-dart">
   <code>
    foo
  .catchError(..., test: (e) =&gt; e is ArgumentError)
  .catchError(..., test: (e) =&gt; e is NoSuchMethodError)
  .then((v) { ... });
   </code>
  </pre>
  <p>
   This method is equivalent to:
  </p>
  <pre class="prettyprint lang-dart">
   <code>
    Future catchError(onError(error),
                  {bool test(error)}) {
  this.then((v) =&gt; v,  // Forward the value.
            // But handle errors, if the [test] succeeds.
            onError: (e, stackTrace) {
              if (test == null || test(e)) {
                if (onError is ZoneBinaryCallback) {
                  return onError(e, stackTrace);
                }
                return onError(e);
              }
              throw e;
            });
}
   </code>
  </pre>
 </section>
 <section class="summary source-code" id="source">
  <h2>
   <span>
    Source
   </span>
  </h2>
  <pre>
   <code class="prettyprint lang-dart">
    Future catchError(Function onError,
                  {bool test(Object error)});
   </code>
  </pre>
 </section>
</div>
